Workbook

Sheet Offering Speed
A1: Name | B1: Rarity | C1: Type | D1: Base Soul Speed | E1: Awakened Bonus | F1: Source
A2: INDIVIDUAL RELICS
A3: Prometheus Torch | B3: SSS | C3: FAME | D3: 4.8 | E3: 4 | F3: Lottery Machine #1 (0.09%), Wishing (0.09%), Hellas Treasure Map, Grandmaster Scrolls (0.81%), Relic Forge (120 Relic RF)
A4: Houmuwu Ding | B4: SSS | C4: CIV | D4: 4.8 | E4: 4 | F4: Wish Box, Lottery Machine #1 (0.09%), Wishing (0.08%), Cathay Treasure Maps (0.01%), Grandmaster Scrolls (0.81%), Relic Forge (120 Relic RF)
A5: Crystal Skull | B5: AAA | C5: ART | D5: 3.6 | E5: 2.8 | F5: Fragment Crafting (1.6%), Lottery Machine #1 (0.03%), Wishing (0.14%), Time Chest (1.5%), Relic Forge (Relic RF 80)
A6: Buddha Tooth Sarira | B6: Blue | C6: FTH | D6: 2 | E6: 2 | F6: Lottery Machine #1 (0.03%), Wishing (0.85%), Bharata Treasure Maps (%)
A7: Death Hallows VII | B7: Green | C7: FTH | D7: 1.2 | F7: Dumbledore Fight II
A8: Crying Boy | B8: Green | C8: ART | D8: 1.2 | F8: I want your collection! Dragon Wish
A9: MAX INDIVIDUAL RELICS | D9: =SUM(D2:E8)
A11: PARTNERS
A12: Prince | D12: 18 | F12: lv30
A14: INTEL
A15: Koryeo | D15: 5
A17: COLLECTOR's TALENTS
A18: Offering Speed | D18: 10
A20: ROCKET UPGRADES
A21: Oracle Hall | D21: 5
A23: RESONANCE
A24: BLUE | D24: 3.6
A25: Divergene Meter | B25: Blue | C25: TECH | F25: Lottery Machine #1 (0.36%), Wishing (13.2%), Time Chest (2%), Novice Scrolls (5%)
A26: Guanery's Violin | B26: Blue | C26: ART | F26: Lottery Machine #1 (0.03%), Wishing (1.2%), Indigent Nobleman (72K B-tads)
A27: Tudor Rose | B27: Blue | C27: FAME | F27: Lottery Machine #1 (0.03%), Wishing (1.2%)
A28: Holmes' Pipe | B28: Blue | C28: CIV | F28: Lottery Machine #1 (0.36%), Wishing (10.3%), Trainee Scrolls (5%)
A29: Dunhuang Painting | B29: Blue | C29: FTH | F29: Lottery Machine #1 (0.03%), Wishing (0.85%)
A30: Our Lady of Kazan | B30: Blue | C30: FTH | F30: Lottery Machine #1 (0.36%), Wishing (10.6%), Trainee Scrolls (5%)
A31: ORANGE | D31: 4
A32: Pandora's Box | B32: SS | C32: FAME | F32: Lottery Machine #1 (0.12%), Wishing (0.11%), Soul Chest(1%), Grandmaster Scrolls (1%), Relic Forge (100 Relic RF)
A33: True Cross | B33: SSS | C33: FTH | F33: Oracle Hall (Earth's Will Cabin) Reward
A34: Arkanrock | B34: SSS | C34: FAME | F34: Eternal Hall (Demon God Cabin) Reward
A35: Maya Slate | B35: SSS | C35: FTH | F35: Wish Box, Lottery Machine #1 (0.09%), Wishing (0.06%), Dragon Chest (0.1%), Grandmaster Scrolls (0.81%), Relic Forge (120 Relic RF)
A36: Royal Celtic Harp | B36: SSS | C36: FTH | F36: Lottery Machine #1 (0.09%), Wishing (0.06%), Grandmaster Scrolls (0.76%)
A37: MAX RESONANCE | D37: =SUM(D24:E36)
A40: Total Soul Offering Speed | B40: =D9+D12+D37+D21+D15+D18
B42: Base | C42: Actual
A43: Speed Example | B43: 8 | C43: =$B43/(1+$B$40/$C$65)
A44: One Round Offering | B44: 240 | C44: =$B44/(1+$B$40/$C$65)
A46: 5 Rounds (hours) | B46: 1200 | C46: =$B46/(1+$B$40/$C$65)
A47: Precooked Offerings (hours) | B47: =48*4 + 8*4
A48: Non-precooked Offerings (hours) | B48: =B46-B47 | C48: =$B48/(1+$B$40/$C$65)
A49: (days) | B49: =B48/$C$66 | C49: =C48/$C$66
...

Sheet Travel Speed
A1: Name | B1: Rarity | C1: Type | D1: Base Travel Speed | E1: Awakened Bonus | F1: Stamp Bonus | G1: Source
A2: INDIVIDUAL RELICS
A3: Voyager 1 | B3: SSS | C3: TECH | D3: 2.4 | G3: Wish Box, Lottery Machine #1 (0.09%), Wishing (0.07%), Murikan Treasure Maps (0.01%), Grandmaster Scrolls (0.81%), Relic Forge (120 Relic RF)
A4: Magellan's Telescope | B4: SSS | C4: FAME | D4: 2.4 | F4: 9 | G4: Lottery Machine #1 (0.09%), Wishing (0.09%), Hellas Treasure Map, Grandmaster Scrolls (0.81%), Relic Forge (120 Relic RF)
A5: Somersault Cloud | B5: SSS | C5: FTH | D5: 2.4 | G5: Wish Pack, Lottery Machine #1 (0.09%), Wishing (0.06%), Super Treasure Maps (0.03%), Grandmaster Scrolls (0.81%), Relic Forge (120 Relic RF), "I want your collection!" Dragon Wish
A6: Travels of Marco Polo | B6: SS | C6: FAME | D6: 2.2 | G6: Lottery Machine #1 (0.12%), Wishing (0.11%), Grandmaster Scrolls (1%), Relic Forge (100 Relic RF), Club Value Pack II ($49.99)
A7: Otto Engine | B7: AAA | C7: TECH | D7: 1.8 | E7: 1.4 | G7: Fragment Crafting (1.6%), Lottery Machine #1 (0.03%), Wishing (0.14%), Tool Chest (1.5%), Relic Forge (80 Relic RF)
A8: Bronze Bird | B8: Blue | C8: FAME | D8: 2 | G8: Cathay Treasure Map (20%)
A9: Flying Broom | B9: Green | C9: FAME | D9: 0.6 | G9: Defeat Ratman
A10: MAX INDIVIDUAL RELICS | D10: =SUM(D3:F9)
A12: GEAR
A13: Tremendous Support | D13: 9.6 | G13: Divine Order Chest (0.8%)
A15: ROCKET UPGRADES
A16: Domain Holograph | D16: 5
A18: FORM SPECIFIC
A19: ZOMBIE
A20: Shroud of Turin | B20: S | C20: FTH | D20: 2 | G20: Fragment Crafting (15.1%), Lottery Machine #1 (0.81%), Wishing (0.53%), Relic Forge (90 Relic RF)
A21: Ludovisi Gaul | B21: Blue | C21: ART | D21: 1 | E21: 1 | G21: Lottery Machine #1 (0.07%), Wishing (3%), Trainee Scrolls (1%), Indigent Nobleman (72K B-tads)
A22: DEMON
A23: Eye of Akamoddo | B23: SS | C23: FTH | D23: 2.2 | G23: Fragment Crafting (4.4%), Lottery Machine #1 (0.24%), Wishing (0.16%), Time Chest (1%), Master Scrolls (1.9%), Grandmaster Scrolls (2.1%), FTH Master Scrolls (9.2%)
A24: Great Wave | B24: Blue | C24: ART | D24: 1 | E24: 1 | G24: Lottery Machine #1 (0.07%), Wishing (3%), Yamato Treasure Maps (20%)
A25: Annabel | B25: Green | C25: CIV | D25: 0.6 | G25: "I want your collection!" Dragon Wish
A26: ANGEL
A27: Golden Chariot | B27: SS | C27: FTH | D27: 2.2 | G27: Fragment Crafting (3.3%), Lottery Machine #1 (0.18%), Wishing (0.12%), Hellas Treasure Maps (%), Grandmaster Scrolls (1.6%)
A28: Guanery's Violin | B28: Blue | C28: ART | D28: 1 | E28: 1 | G28: Lottery Machine #1 (0.03%), Wishing (1.2%), Indigent Nobleman (72K B-tads)
A29: MUTANT
A30: Element R | B30: S | C30: TECH | D30: 2 | G30: Fragment Crafting (17.8%), Lottery Machine #1 (0.81%), Wishing (0.65%), Relic Forge (90 Relic RF)
A31: Torpedo Swimsuit | B31: Blue | C31: TECH | D31: 1 | E31: 1 | G31: Lottery Machine #1 (0.03%), Wishing (1.1%), Evolution Chest (2%)
A32: MECHA
A33: Skyweb Hub | B33: SS | C33: TECH | D33: 2.2 | G33: Koryeon Domain, Fragment Crafting (5.2%), Lottery Machine #1 (0.24%), Wishing (0.19%), Super Treasure Maps (5%), Master Scrolls (1.9%), Grandmaster Scrolls (2.1%), TECH Master Scrolls (9.2%)
A34: Arirange Satellite | B34: Blue | C34: TECH | D34: 1 | E34: 1 | G34: Lottery Machine #1 (0.03%), Wishing (1.1%), Nebula Chest (2%)
A35: DRAGON
A36: Phoenix Feather | B36: SSS | C36: FTH | D36: 2.4 | G36: Lottery Machine #1 (0.09%), Wishing (0.06%), Evolution Chest (0.01%), Grandmaster Scrolls (0.81%), Relic Forge (120 Relic RF)
A37: Dunhuang Painting | B37: Blue | C37: FTH | D37: 1 | E37: 1 | G37: Lottery Machine #1 (0.03%), Wishing (0.85%)
A38: MAX FORM SPECIFIC | D38: =MAX(SUM(D20:E21), SUM(D23:E25), SUM(D27:E28), SUM(D30:E31), SUM(D33:E34), SUM(D36:E37))
A40: RESONANCE
A41: BLUE | D41: 1.8
A42: Flyer I | B42: Blue | C42: TECH | G42: Lottery Machine #1 (0.03%), Wishing (1.1%)
A43: Storyteller | B43: Blue | C43: ART | G43: Lottery Machine #1 (0.36%), Wishing (15%), Trainee Scrolls (5%)
A44: Dragon Crystal | B44: Blue | C44: FTH | G44: Dragon Gene Research Tier 2
...

Sheet Gene Research
A1: Name | B1: Rarity | C1: Type | D1: Research Speed | E1: Awakening Research Speed | F1: Cells Cost | G1: Awakening Cells Cost | H1: Btad Cost | I1: Awakening Btad Cost | J1: Free Speedup (min) | K1: Awakening Free Speedup | L1: Source
A2: INDIVIDUAL RELICS
A3: Double Helix DNA | B3: SSS | C3: TECH | D3: 2.4 | E3: 2 | H3: 4.8 | J3: 36 | L3: Lottery Machine #1 (0.09%), Wishing (0.07%), Grandmaster Scrolls (0.81%), Relic Forge (120 Relic RF)
A4: The Analects | B4: SSS | C4: CIV | D4: 2.4 | E4: 2 | H4: 4.8 | J4: 36 | L4: Wish Box, Lottery Machine #1 (0.09%), Wishing (0.08%), Grandmaster Scrolls (0.81%), Relic Forge (120 Relic RF)
A5: Voynich Script | B5: AAA | C5: CIV | H5: 3.6 | I5: 2.8 | L5: Form Evo Pack
A6: MAX INDIVIDUAL RELICS | D6: =sum(D3:E5) | F6: =sum(F3:G5) | H6: =sum(H3:I5) | J6: =sum(J3:K5)
A8: PARTNER
A9: Toraemon | D9: 30 | L9: lv30
A11: ORGANS
A12: Savant Eye | D12: 3 | J12: 15 | L12: Organ Chest (3% chance), 1st Purchase Gift Pack Day 3 Reward($Any)
A13: Brainworm Neuron | J13: 15 | L13: Organ Value Pack I ($14.99)
A14: MAX ORGANS | D14: =sum(D12:E13) | F14: =sum(F12:G13) | H14: =sum(H12:I13) | J14: =sum(J12:K13)
A16: NEBULA
A17: Microscopium | D17: 1.6 | H17: 3.2 | J17: 48 | L17: Beta Galaxy
A18: Circinus | D18: 6 | L18: Delta Galaxy
A19: MAX NEBULA | D19: =SUM(D17:D18) | F19: =SUM(F17:F18) | H19: =SUM(H17:H18) | J19: =SUM(J17:J18)
A21: COLLECTORS TALENTS
A22: Genetic Engineering I | D22: 15 | L22: 15 Purple Talent Points
A23: Genetic Engineering II | D23: 15 | J23: 150 | L23: 15 Orange Talent Points
A24: Gene SPD II (purple) | D24: 20 | L24: 15 Purple Talent Points
A25: Gene SPD II (orange) | D25: 20 | J25: 240 | L25: 15 Orange Talent Points
A26: MAX COLLECTORS TALENTS | D26: =sum(D22:E25) | F26: =sum(F22:G25) | H26: =sum(H22:I25) | J26: =sum(J22:K25)
A28: FUNGUS
A29: Purple | D29: 3 | L29: 500 Purple Fungus Consumed
A31: ROCKET UPGRADES
A32: Silence Hall | D32: 5 | J32: 120 | L32: lv5
A34: AVATAR BONUS
A35: Event Avatar | D35: 5 | F35: 5 | H35: 5 | J35: 20
A37: RESONANCE
A38: BLUE
A39: Research Speed | D39: 1.8
A40: Chakana | B40: Blue | C40: FTH | L40: Lottery Machine #1 (0.03%), Wishing (0.85%), Soul Chest (2%)
A41: Great Wave | B41: Blue | C41: ART | L41: Lottery Machine #1 (0.07%), Wishing (3%), Yamato Treasure Maps (20%)
A42: Janssen Microscope | B42: Blue | C42: TECH | L42: Lottery Machine #1 (0.07%), Wishing (2.6%), Evolution Chest (2%), Novice Scrolls (1%)
A43: Royal Doll | B43: Blue | C43: CIV | L43: Lottery Machine #1 (0.03%), Wishing (0.82%)
A44: Mask of Zorro | B44: Blue | C44: FAME | L44: Lottery Machine #1 (0.03%), Wish (1.2%), Zorro (B+B Reward)
A45: Moai | B45: Blue | C45: FTH | L45: Lottery Machine #1 (0.36%), Wishing (10.6%), Soul Chest (2%), Novice Scrolls (5%)
A46: PURPLE
A47: Research Speed | D47: 2
A48: Fuchun Mountains | B48: AA | C48: FTH | L48: Fragment Crafting (3.9%), Lottery Machine #1 (0.08%), Wishing (0.36%), Expert Scrolls (0.95%)
...

Sheet Cells Gained
A1: Name | B1: Rarity | C1: Type | D1: Zombie Cells | E1: Zombie Cells (Awakened) | F1: Demon Cells | G1: Demon Cells (Awakened) | H1: Angel Cells | I1: Angel Cells (Awakened) | J1: Mutant Cells | K1: Mutant Cells (Awakened) | L1: Mecha Cells | M1: Mecha Cells (Awakened) | N1: Source
A2: INDIVIDUAL RELICS
A3: Shroud of Turin | B3: S | C3: FTH | D3: 10 | E3: 10 | N3: Fragment Crafting (15.1%), Lottery Machine #1 (0.81%), Wishing (0.53%), Relic Forge (90 Relic RF)
A4: Eye of Akamoddo | B4: SS | C4: FTH | F4: 11 | G4: 10 | N4: Fragment Crafting (4.4%), Lottery Machine #1 (0.24%), Wishing (0.16%), Time Chest (1%), Master Scrolls (1.9%), Grandmaster Scrolls (2.1%), FTH Master Scrolls (9.2%)
A5: Time-Travel Box | B5: SS | C5: FAME | H5: 11 | I5: 10 | N5: Fragment Crafting (4.6%), Lottery Machine #1 (0.18%), Wishing (0.17%), Dragon Chest (5%), Grandmaster Scrolls (1.6%)
A6: Element R | B6: S | C6: TECH | J6: 10 | K6: 10 | N6: Fragment Crafting (17.8%), Lottery Machine #1 (0.81%), Wishing (0.65%), Relic Forge (90 Relic RF)
A7: SkyWeb Hub | B7: SS | C7: TECH | L7: 11 | M7: 10 | N7: Koryeon Domain, Fragment Crafting (5.2%), Lottery Machine #1 (0.24%), Wishing (0.19%), Super Treasure Maps (5%), Master Scrolls (1.9%), Grandmaster Scrolls (2.1%), TECH Master Scrolls (9.2%)
A8: Prehistoric Fossil | B8: AAA | C8: CIV | D8: 5.4 | F8: 5.4 | H8: 5.4 | J8: 5.4 | L8: 5.4 | N8: Fragment Crafting (1.5%), Lottery Machine #1 (0.03%), Wishing (0.14%), Time Chest (1.5%), Relic Forge (80 Relic RF)
A9: Imperial Lamp | B9: Blue | C9: ART | D9: 5 | E9: 5 | N9: Lottery Machine #1 (0.07%), Wishing (3%), Novice Scrolls (1%)
A10: Ranjyatai Incense | B10: Blue | C10: FTH | F10: 5 | G10: 5 | N10: Lottery Machine #1 (0.07%), Wishing (2.1%), Novice Scrolls (1%)
A11: Gone with the Wind | B11: Blue | C11: CIV | H11: 5 | I11: 5 | N11: Murikan Treasure Maps (20%)
A12: Izu Dancer | B12: Blue | C12: CIV | J12: 5 | K12: 5 | N12: Lottery Machine #1 (0.03%), Wishing (0.82%)
A13: Euclid's Elements | B13: Blue | C13: TECH | L13: 5 | M13: 5 | N13: Lottery Machine #1 (0.03%), Wishing (1.1%), Hellenic Treasure Map (%)
A14: MAX INDIVIDUAL RELICS | D14: =sum(D2:E13) | F14: =sum(F2:G13) | H14: =sum(H2:I13) | J14: =sum(J2:K13) | L14: =sum(L2:M13)
A16: ORGANS
A17: Evil Pattern | D17: 5 | F17: 5 | H17: 5 | J17: 5 | L17: 5 | N17: Tutorial (Evolution)
A18: Demon Spine | D18: 4 | F18: 4 | N18: Demon God Matrix (Demon God Rocket Cabin) Reward
A19: Eden Neuron | H19: 4 | L19: 4 | N19: Garden of Eden (Earth's Will Rocket Cabin) Reward
A20: Dark Matter's Heart | D20: 4 | F20: 4 | H20: 4 | J20: 8 | L20: 4 | N20: Dark Matter Reactor (Rebel Cabin) Reward
A21: Alveolus of Gaia | D21: 20 | F21: 20 | H21: 20 | J21: 20 | L21: 20 | N21: Feast Rewards
A22: MAX ORGANS | D22: =sum(D17:E21) | F22: =sum(F17:G21) | H22: =sum(H17:I21) | J22: =sum(J17:K21) | L22: =sum(L17:M21)
A24: ROCKET CABINS
A25: Eternal Hall | D25: 10 | F25: 10 | H25: 10 | J25: 10 | L25: 10 | N25: Demon God Cabin
A26: Silence Hall | D26: 10 | N26: Rebel Cabin
A27: Apocalypse Hall | F27: 10 | N27: Demon God Cabin
A28: Oracle Hall | H28: 10 | N28: Earth's Will Cabin
A29: Revelation Hall | J29: 10 | N29: Earth's Will Cabin
A30: Steel Hall | L30: 10 | N30: Rebel Cabin
A31: MAX ROCKET CABIN | D31: =sum(D25:E30) | F31: =sum(F25:G30) | H31: =sum(H25:I30) | J31: =sum(J25:K30) | L31: =sum(L25:M30)
A33: RESONANCE
A34: PURPLE
A35: Zombie | D35: 6
A36: Voynich Script | B36: AAA | C36: CIV | N36: Form Evo Pack
A37: The Nutcracker | B37: AAA | C37: ART | N37: Fragment Crafting (1.6%), Lottery Machine #1 (0.03%), Wishing (0.14%), Relic Forge (80 Relic RF)
A38: Demon | F38: 6
A39: Andersen's Fairytales | B39: AAA | C39: CIV | N39: Fragment Crafting (1.5%), Lottery Machine #1 (0.03%), Wishing (0.14%), Relic Forge (80 Relic RF)
A40: Magic Mirror | B40: AAA | C40: FTH | N40: Fragment Crafting (1.5%), Lottery Machine #1 (0.03%), Wishing (0.14%), Relic Forge (80 Relic RF)
A41: Angel | H41: 8
A42: Napoleon Painting | B42: AAA | C42: ART | N42: Fragment Crafting (1.6%), Lottery Machine #1 (0.03%), Wishing (0.14%), Relic Forge (Relic RF x80)
A43: Phoenician Tablet | B43: AA | C43: CIV | N43: Fragment Crafting (3.7%), Lottery Machine #1 (0.8%), Wishing (0.34%), Kemetic Treasure Maps (10%), Expert Scrolls (0.95%)
...

Sheet Museum
B1: Rarity | C1: AFFCT | D1: Main AFFCT | E1: Total AFFCT | F1: Medal Output | G1: Wish Coin Cost | H1: Btad Output | I1: AFFCT Boost | J1: Effective AFFCT | K1: Total Effective AFFCT | L1: Source
A2: KORYEO
A3: INDIVIDUAL RELICS
A4: Ordinary Casket | B4: SSS | C4: FAME | D4: 104 | E4: 347 | F4: 30 | I4: 15 | J4: =D4+I4 | K4: =E4+I4 | L4: Relic Power Rewards (8M - 15M Relic Power)
A5: Leaf of Yggdrasil | B5: S | C5: FAME | D5: 100 | E5: 332 | J5: =D5+I5 | K5: =E5+I5 | L5: Fragment Crafting (20.7%), Lottery Machine #1 (0.81%), Wishing (0.75%), Super Treasure Map (15%), Master Scrolls (6.5%), FAME Master Scrolls (31.5%), Relic Forge (90 Relic RF)
A6: Twin Lions Lantern | B6: AA | C6: FAME | D6: 70 | I6: 10 | J6: =D6+I6 | L6: Museum Operation Reward
A7: Mischief Map | B7: AA | C7: FAME | D7: 71 | J7: =D7+I7 | L7: Domain Exploration Reward
A8: View of Le Gras | B8: A | C8: FAME | D8: 64 | J8: =D8+I8 | L8: Lottery Machine #2 (0.55%)
A9: Peter Pan's Flute | B9: Blue | C9: FAME | D9: 46 | J9: =D9+I9 | L9: Lottery Machine #1 (0.03%), Wishing (1.2%), Britland Treasure Map (20%)
A10: Annals of Joseon | B10: Blue | C10: FAME | D10: 45 | J10: =D10+I10 | L10: Koryeo Treasure Map (20%)
A11: Hun Min Jong Um | B11: Blue | C11: FAME | D11: 45 | J11: =D11+I11 | L11: Koryeo Treasure Map (20%)
A12: King's Gayageum | B12: SSS | C12: ART | D12: 107 | E12: 362 | I12: 15 | J12: =D12+I12 | K12: =E12+I12 | L12: Daily Pack Relic #7
A13: Irises | B13: SSS | C13: ART | D13: 106 | E13: 362 | H13: 3000 | I13: 15 | J13: =D13+I13 | K13: =E13+I13 | L13: Star Chart Shop
A14: Suger's Eagle | B14: S | C14: ART | D14: 99 | E14: =48+99+63+66+56 | J14: =D14+I14 | K14: =E14+I14 | L14: Lottery Machine #2 (1.59%)
A15: Death of Marat | B15: AA | C15: ART | D15: 69 | J15: =D15+I15 | L15: Fragment Crafting (3.9%), Lottery Machine #1 (0.08%), Wishing (0.36%), Expert Scrolls (0.95%)
A16: King Dangun Statue | B16: S | C16: FTH | D16: 99 | E16: 332 | G16: 30 | J16: =D16+I16 | K16: =E16+I16 | L16: Fragment Crafting (15.1%), Lottery Machine #1 (0.81%), Wishing (0.81%), Koryeo Treasure Map (5%), Relic Forge (90 Relic RF)
A17: Tree of Life | B17: AAA | C17: FTH | D17: 72 | I17: 10 | J17: =D17+I17 | L17: Fragment Crafting (1.5%), Wishing (0.03%), Lottery Machine #1 (0.14%), Fungus chest (1.5%), Relic Forge (80 Relic RF), Home Value Pack II ($4.99)
A18: Tyr's Arm | B18: AA | C18: FTH | D18: 66 | J18: =D18+I18 | L18: Fragment Crafting (3.8%), Lottery Machine #1 (0.08%), Wishing (0.35%), Expert Scrolls (0.95%)
A19: Dragon Crystal | B19: Blue | C19: FTH | D19: 45 | J19: =D19+I19 | L19: Dragon Gene Research Tier 2
A20: Aries | B20: SSS | C20: CIV | D20: 110 | E20: 365 | J20: =D20+I20 | K20: =E20+I20 | L20: Supreme Relic ($2k)
A21: Divine Comedy | B21: SSS | C21: CIV | D21: 106 | E21: 362 | F21: 30 | J21: =D21+I21 | K21: =E21+I21 | L21: Lottery Machine #1 (0.09%), Wishing (0.08%), Grandmaster Scrolls (0.81%), Relic Forge (120 Relic RF)
A22: Prehistoric Fossil | B22: AAA | C22: CIV | D22: 75 | J22: =D22+I22 | L22: Fragment Crafting (1.5%), Lottery Machine #1 (0.03%), Wishing (0.14%), Time Chest (1.5%), Relic Forge (80 Relic RF)
A23: Koryeon Sutra | B23: AAA | C23: CIV | D23: 73 | J23: =D23+I23 | L23: Fragment Crafting (1.5%), Lottery Machine #1 (0.03%), Wishing (0.14%), Koryeon Treasure Maps (10%), Relic Forge (80 Relic RF)
A24: Im's Arrow | B24: Blue | C24: CIV | D24: 44 | J24: =D24+I24 | L24: Lottery Machine #1 (0.07%), Wishing (2.1%), Novice Scrolls (1%)
A25: Energy Missile | B25: SSS | C25: TECH | D25: 109 | E25: 362 | I25: 15 | J25: =D25+I25 | K25: =E25+I25 | L25: Clover Vendor Reward
A26: Devol's Robot | B26: S | C26: TECH | D26: 97 | E26: 332 | I26: 15 | J26: =D26+I26 | K26: =E26+I26 | L26: Fragment Crafting (17.8%), Wishing (0.65%), Ad Chest (3%), Master Scrolls (6.5%), TECH Master Scrolls (31.5%), Relic Forge (90 Relic RF)
A27: Artificial Blackhole | B27: SSS | C27: TECH | D27: 106 | E27: 362 | J27: =D27+I27 | K27: =E27+I27 | L27: Wish Box, Lottery Machine #1 (0.09%), Wishing (0.07%), Demon God Chest (0.1%), Grandmaster Scrolls (0.81%), Relic Forge (120 Relic RF), Nebula Chest (0.01%)
A28: Arirang Satillite | B28: Blue | C28: TECH | D28: 46 | J28: =D28+I28 | L28: Lottery Machine #1 (0.03%), Wishing (1.1%), Nebula Chest (2%)
A31: MUSEUM LAYOUT | C31: Restriction | D31: Used | E31: Museum Score | F31: Medal Output | G31: Wish Coin Cost | H31: Btad Output
A32: 1 | B32: ALL | D32: Irises | E32: =K13 | H32: =H13
A33: 2 | B33: FTH | C33: King Dangun Statue | D33: King Dangun Statue | E33: =J16 | G33: =G16
A34: 3 | B34: FAME | C34: Hun Min Jong Um | D34: Hun Min Jong Um | E34: =J11
A35: 4 | B35: FAME | C35: Annals of Joseon | D35: Annals of Joseon | E35: =J10
A36: 5 | B36: FAME | D36: Ordinary Casket | E36: =J4 | F36: =F4
A37: 6 | B37: ART | D37: King's Gayageum | E37: =J12
A38: 7 | B38: ART | D38: FILLER | E38: 100
A39: 8 | B39: ART | D39: FILLER | E39: 100
A40: 9 | B40: FTH | D40: FILLER | E40: 100
A41: 10 | B41: FTH | D41: FILLER | E41: 100
A42: 11 | B42: CIV | D42: Aries | E42: =J20
...

Sheet Rocket Cabin Effects
B1: Rarity | C1: Type | D1: Base Effect | E1: Base Effect (Awakened) | F1: Source
A4: REBEL CABIN
A5: Jiuzhang | B5: SSS | C5: TECH | D5: 12 | F5: Lottery Machine #2 (0.12%)
A7: Resonance: Orange | D7: 10
A8: Mysterious Relic | B8: SSS | F8: Unknown
A9: Atlantis Crystal | B9: SSS | C9: FTH | F9: Lottery Machine #2 (0.12%), Relic Forge (120 RF)
A10: Lawrence's Cyclotron | B10: SSS | C10: TECH | F10: Lottery Machine #2 (0.12%)
A11: Science Magazine Vol.1 | B11: SSS | C11: FAME | F11: Lottery Machine #2 (0.12%)
A12: Phaistos Disc | B12: SSS | C12: CIV | F12: Lottery Machine #2 (0.12%), Relic Forge (120 RF)
A13: MAX REBEL CABIN | D13: =sum(D5:E12)
A16: Photonic Communicator (Angel)
A17: Cross of Lorraine | B17: SS | C17: FAME | D17: 88 | F17: Lottery Machine #2 (?%)
A18: Akebono | B18: Blue | C18: TECH | D18: 40 | E18: 40 | F18: Lottery Machine #2 (?%)
A20: Resonance: Orange | D20: 56
A21: Rutherford Model | B21: SS | C21: TECH | F21: Lottery Machine #2 (0.23%)
A22: SC Energy Storage Unit | B22: SS | C22: TECH | F22: Lottery Machine #2 (0.47%)
A23: MAX PHOTONIC COMMUNICATOR | D23: =sum(D17:E22)
A26: Prismatic Armor (Mecha)
A27: Eight Proposals | B27: SS | C27: CIV | D27: 88 | F27: Lottery Machine #2 (0.23%)
A28: Model G Loom | B28: Blue | C28: FAME | D28: 40 | E28: 40 | F28: Lottery Machine #2 (0.03%)
A30: Resonance: Orange | D30: 56
A31: Crime and Punishment | B31: SSS | C31: CIV | F31: Lottery Machine #2 (0.12%)
A32: Palermo Stone | B32: SSS | C32: TECH | F32: Lottery Machine #2 (1.59%), Rift Treasure Maps (5%)
A33: MAX PRISMATIC ARMOR | D33: =sum(D27:E32)
A36: Auto-reload Device (Demon)
A37: Eight Proposals | B37: SS | C37: CIV | D37: 88 | F37: Lottery Machine #2 (0.23%)
A38: The Knotted Pistol | B38: Blue | C38: FAME | D38: 40 | E38: 40 | F38: Lottery Machine #2 (0.03%)
A39: MAX AUTO-RELOAD DEVICE | D39: =sum(D37:E38)
A42: Biochemical MOD Module (Zombie)
A43: Swimming Reindeer | B43: SS | C43: ART | D43: 88 | F43: Lottery Machine #2 (0.35%)
A44: Bastet Bronze Statue | B44: Blue | C44: FTH | D44: 40 | E44: 40 | F44: Lottery Machine #2 (0.03%), Indigent Nobleman (72K B-tads)
A45: MAX BIOCHEMICAL MOD MODULE | D45: =sum(D43:E44)
A48: Anti-gravity Device (Mecha)
A49: Oxus Treasure | B49: SSS | C49: ART | D49: 96 | F49: Lottery Machine #2 (0.12%), Relic Forge (120 RF)
A50: DNA Microarray | B50: AA | C50: TECH | D50: 64 | E50: 56 | F50: Lottery Machine #2 (0.12%)
A52: Resonance: Orange | D52: 64
A53: Hevelius Chart | B53: SSS | C53: CIV | F53: Star Chart Shop
A54: Veiled Lady | B54: SS | C54: ART | F54: Lottery Machine #2 (0.47%), Indigent Nobleman (570K B-tads)
A55: The Kiss | B55: S | C55: FAME | F55: Lottery Machine #2 (1.59%)
A56: MAX ANTI-GRAVITY DEVICE | D56: =sum(D49:E55)
...

Sheet Minion Boosts
A1: GENERAL
A2: HP | B2: Rarity | C2: Type | D2: Base | E2: Awakening Base | F2: Percentage | G2: Awakening Percentage | H2: Per Minion | I2: Per Minion Boost | J2: Source | O2: HP (Per Minion) | P2: HP (%) | Q2: ATK (Per Minion) | R2: ATK (%) | S2: RUSH (Per Minion) | T2: RUSH (%) | U2: DEF (Per Minion) | V2: DEF (%) | W2: HARD (Per Minion) | X2: HARD (%)
A3: Last Self Portrait | B3: SSS | C3: ART | D3: 900 | E3: 900 | H3: 60 | I3: =(D3+E3)/H3 | J3: Daily Pack Relic #15 | N3: General | O3: =I37 | P3: =F37 | Q3: =I91 | R3: =F91 | S3: =I131 | T3: =F131 | U3: =I167 | V3: =F167 | W3: =I201 | X3: =F201
A4: Wild Pansy's Juice | B4: AAA | C4: FTH | D4: 360 | E4: 280 | H4: 30 | I4: =(D4+E4)/H4 | J4: Gastric Pouch | N4: Zombie | O4: =I227 | P4: =F227 | Q4: =I254 | R4: =F254 | S4: =I275 | T4: =F275 | U4: =I294 | V4: =F294 | W4: =I308 | X4: =F308
A5: Arianrhod's Wheel | B5: SSS | C5: FTH | D5: 1200 | H5: 60 | I5: =(D5+E5)/H5 | J5: Daily Pack Relic #47
A6: Treasure Island | B6: AAA | C6: CIV | D6: 320 | E6: 280 | H6: 30 | I6: =(D6+E6)/H6 | J6: Time Beacon Reward | N6: Demon | O6: =I332 | P6: =F332 | Q6: =I358 | R6: =F358 | S6: =I380 | T6: =F380 | U6: =I399 | V6: =F399 | W6: =I414 | X6: =F414
A7: Cancer | B7: SSS | C7: ART | D7: 1600 | H7: 100 | I7: =(D7+E7)/H7 | J7: Supreme Relic #12 | N7: Angel | O7: =I439 | P7: =F439 | Q7: =I467 | R7: =F467 | S7: =I487 | T7: =F487 | U7: =I507 | V7: =F507 | W7: =I522 | X7: =F522
A8: Pisces | B8: SSS | C8: FAME | D8: 1600 | H8: 100 | I8: =(D8+E8)/H8 | J8: Supreme Relic #20 | N8: Mutant | O8: =I546 | P8: =F546 | Q8: =I572 | R8: =F572 | S8: =I590 | T8: =F590 | U8: =I610 | V8: =F610 | W8: =I624 | X8: =F624
A9: Scorpio | B9: SSS | C9: CIV | D9: 1600 | H9: 100 | I9: =(D9+E9)/H9 | J9: Supreme Relic #16 | N9: Mecha | O9: =I649 | P9: =F649 | Q9: =I675 | R9: =F675 | S9: =I697 | T9: =F697 | U9: =I715 | V9: =F610 | W9: =I733 | X9: =F733
A10: Ludovisi Ares | B10: SSS | C10: FTH | D10: 900 | H10: 60 | I10: =(D10+E10)/H10 | J10: Star Chart Shop | N10: Dragon | O10: =I762 | P10: =F762 | Q10: =I792 | R10: =F792 | S10: =I819 | T10: =F819 | U10: =I842 | V10: =F842 | W10: =I867 | X10: =F867
A11: Scales of Astraea | B11: SSS | C11: FTH | D11: 900 | H11: 60 | I11: =(D11+E11)/H11 | J11: Star Chart Shop
A12: Trojan Horse | B12: SSS | C12: FAME | D12: 900 | H12: 60 | I12: =(D12+E12)/H12 | J12: Lottery Machine #1 (0.09%), Wishing (0.09%), Grandmaster Scrolls (0.81%), Relic Forge (120 Relic RF)
A13: Ebers Papyrus | B13: SSS | C13: TECH | F13: 2.4 | G13: 2 | J13: Wish Box Album Relic #2
A14: Ink Chrysanths | B14: SSS | C14: ART | F14: 2.4 | G14: 2 | J14: Lottery Machine #2 (0.11%)
A15: La Marseillaise | B15: SSS | C15: ART | F15: 2.4 | G15: 2 | J15: Star Chart Shop
A16: Discobolus | B16: SSS | C16: ART | F16: 2.4 | J16: Lottery Machine #2 (?%)
A17: Orphic Egg | B17: SSS | C17: FTH | F17: 2.4 | J17: Lottery Machine #2 (0.12%), Relic Forge (120 RF)
A19: Resonance: Orange | D19: 630 | H19: 60 | I19: =(D19+E19)/H19
A20: Shahnameh | B20: SSS | C20: CIV | J20: Lottery Machine #2 (0.12%)
A21: The Art of War | B21: SSS | C21: CIV | J21: Wish Box, Lottery Machine #1 (0.09%), Wishing (0.08%), Grandmaster Scrolls (0.81%), Relic Forge (120 Relic RF)
A22: Resonance: Orange | D22: 630 | H22: 60 | I22: =(D22+E22)/H22
A23: Smug's Chalice | B23: SS | C23: FAME | J23: T7.5 Dragon Gene Research
A24: Imperial Jade | B24: S | C24: FAME | J24: Fragment Crafting (20.7%), Lottery Machine #1 (0.81%), Wishing (0.75%), Cathay Treasure Maps (5%), Relic Forge (90 Relic RF)
A25: Resonance: Purple | D25: 240 | H25: 30 | I25: =(D25+E25)/H25
A26: Prehistoric Fossil | B26: AAA | C26: CIV | J26: Fragment Crafting (1.5%), Lottery Machine #1 (0.03%), Wishing (0.14%), Time Chest (1.5%), Relic Forge (80 Relic RF)
A27: Koryeon Sutra | B27: AAA | C27: CIV | J27: Fragment Crafting (1.5%), Lottery Machine #1 (0.03%), Wishing (0.14%), Koryeon Treasure Maps (10%), Relic Forge (80 Relic RF)
A28: Resonance: Blue | D28: 60 | H28: 10 | I28: =(D28+E28)/H28
A29: Matsushima Pot | B29: Blue | C29: CIV | J29: Lottery Machine #2 (0.07%)
A30: Pompeii | B30: Blue | C30: ART | J30: Lottery Machine #2 (0.03%)
A31: The Moon and Sixpence | B31: Blue | C31: CIV | J31: Lottery Machine #2 (0.03%)
A32: Resonance: Orange | F32: 1.8
A33: Grimmy Award | B33: SS | C33: FAME | J33: Lottery Machine #2 (0.35%)
A34: Mysterious Relic | B34: SSS | J34: Unknown
A35: Mysterious Relic | B35: SSS | J35: Unknown
A36: Species Plantarum | B36: SSS | C36: TECH | J36: Star Chart Shop
A37: TOTAL HP | F37: =sum(F3:G36) | I37: =sum(I3:I36)
A40: ATK | B40: Rarity | C40: Type | D40: Base | E40: Awakening Base | F40: Percentage | G40: Awakening Percentage | H40: Per Minion | I40: Per Minion Boost | J40: Source
A41: EPR Paradox | B41: SSS | C41: TECH | D41: 120 | E41: 100 | H41: 60 | I41: =(D41+E41)/H41 | J41: Wish Box Relic #8
A42: Infin. Improb. Eng. | B42: SSS | C42: TECH | D42: 120 | E42: 100 | H42: 60 | I42: =(D42+E42)/H42 | J42: Daily Pack Relic #51
A43: Capricorn | B43: SSS | C43: TECH | D43: 160 | H43: 100 | I43: =(D43+E43)/H43 | J43: Supreme Relic #18
...

Sheet Leadership
A1: BASE | B1: (Credit FunFreddyBon)
A2: Base Leadership | D2: 10 | F2: Starter leadership
A3: MAX BASE LEADERSHIP | D3: =D2
A6: INDIVIDUAL RELICS
A7: Pisces | B7: SSS | C7: FAME | D7: 20 | E7: 20 | F7: Supreme Relic #20
A8: Bill of Rights | B8: SSS | C8: FAME | D8: 15 | E8: 10 | F8: Daily Silver Pack #8
A9: Apollo Program | B9: SSS | C9: FAME | D9: 15 | E9: 10 | F9: Daily Silver Pack #11
A10: Trojan Horse | B10: SSS | C10: FAME | D10: 12 | E10: 5 | F10: Lottery Machine No.1 (0.09%), Alchemy Furnace (0.08%), Grandmaster Scrolls (0.75%), Relic Forge (120)
A11: Terracotta Warrior | B11: SSS | C11: FAME | D11: 12 | E11: 5 | F11: Lottery Machine No.2 (0.11%), Relic Forge 2 (120)
A12: The Prince | B12: SSS | C12: FAME | D12: 12 | E12: 5 | F12: Lottery Machine No.2 (0.11%)
A13: Nightingale Medal | B13: SSS | C13: FAME | D13: 12 | E13: 5 | F13: Lottery Machine No.2 (0.11%)
A14: Cross of Will | B14: SSS | C14: FAME | D14: 12 | E14: 5 | F14: Secret Mission (Bird)
A15: Napoleonic Code | B15: SSS | C15: FAME | D15: 12 | E15: 5 | F15: Daily Pack #11
A16: Hugo Award | B16: SSS | C16: FAME | D16: 12 | E16: 5 | F16: Travelers Pack #4
A17: Modern Times | B17: SSS | C17: FAME | D17: 12 | E17: 5 | F17: Badge Shop #4
A18: Bust of Hammurabi | B18: SSS | C18: FAME | D18: 12 | E18: 5 | F18: Lottery Machine No.3 (?%)
A19: Convention on the Rights of the Child | B19: SSS | C19: FAME | D19: 12 | F19: Lottery Machine No.2 (?%)
A20: Woman at Her Toilette | B20: SSS | C20: ART | D20: 20 | E20: 20 | F20: Minion Skin Lottery
A21: Golden Chan-hee | B21: SSS | C21: ART | D21: 15 | E21: 10 | F21: 4th Anniversary Event, Badge Shop (1000 medals) starting 5th year of launch
A22: Seated Voltaire | B22: SSS | C22: ART | D22: 12 | E22: 5 | F22: Wish Relic #1
A23: Capitoline Wolf | B23: SSS | C23: ART | D23: 12 | E23: 5 | F23: Lottery Machine No.2(0.11%)
A24: Woman with a Veil | B24: SSS | C24: ART | D24: 12 | E24: 5 | F24: Lottery Machine No.3 (?%)
A25: Han Hee-Jae's Night Banquet | B25: SSS | C25: ART | D25: 12 | E25: 5 | F25: Lottery Machine No.3 (?%)
A26: Apollo & Daphne | B26: SSS | C26: ART | D26: 12 | E26: 5 | F26: Daily Pack #27
A27: Arnolfini Portrait | B27: SSS | C27: ART | D27: 12 | E27: 5 | F27: Unknown
A28: Grace of Divine Dragon | B28: SSS | C28: ART | D28: 12 | E28: 5 | F28: Unknown
A29: Aurelius on Horse | B29: SSS | C29: ART | D29: 12 | F29: Unknown
A30: Laocoon | B30: SSS | C30: ART | D30: 12 | F30: Lottery Machine No.3 (?%)
A31: The Bronze Age | B31: SSS | C31: ART | D31: 12 | F31: Daily Pack #31
A32: Water Lilies | B32: SSS | C32: ART | D32: 12 | F32: Travelers Relic #9
A33: The Yellow Christ | B33: SSS | C33: ART | D33: 12 | F33: Travelers Pack #?
A34: Tyet | B34: SSS | C34: FTH | D34: 15 | E34: 10 | F34: Unknown
A35: Golden Snail | B35: SSS | C35: FTH | D35: 15 | E35: 10 | F35: 1st Anniversary Event, Badge Shop (1000 medals) starting 2nd year of launch
A36: The Silver Key | B36: SSS | C36: FTH | D36: 12 | E36: 5 | F36: Lottery Machine No.2 (0.11%), Rift Treasure Maps (0.01%)
A37: Holy Grail | B37: SSS | C37: FTH | D37: 12 | E37: 5 | F37: Lottery Machine No.2 (0.11%)
A38: Colossus of Rhodes | B38: SSS | C38: FTH | D38: 12 | E38: 5 | F38: Badge Shop
A39: Emerald Tablet | B39: SSS | C39: FTH | D39: 12 | E39: 5 | F39: Daily Pack #24
A40: Jerusalem Walls | B40: SSS | C40: FTH | D40: 12 | E40: 5 | F40: Lottery Machine No.3 (?%)
A41: Ra's Solar Barque | B41: SSS | C41: FTH | D41: 12 | E41: 5 | F41: Unknown
A42: Atenism | B42: SSS | C42: FTH | D42: 12 | E42: 5 | F42: Unknown
...

Sheet Tadpole Pond
A1: Name | B1: Rarity | C1: Type | D1: Base Output | E1: Awakening Output | F1: Base Cap | G1: Awakening Cap | H1: W-tad Generation | I1: Awakening W-tad Gen | J1: AFFECT Boost | K1: Source
A2: INDIVIDUAL RELICS
A3: Faust | B3: SSS | C3: CIV | D3: 24 | E3: 20 | H3: 24 | K3: Wish Box, Lottery Machine #1 0.09%), Wishing (0.08%), Grandmaster Scrolls (0.81%), Relic Forge (120 Relic RF)
A4: Golden Wheat | B4: SSS | C4: ART | D4: 24 | E4: 20 | K4: Wish Pack, Lottery Machine #1 (0.09%), Wishing (0.08%), Yamato Treasure Maps (0.01%), Grandmaster Scrolls (0.81%), Relic Forge (120 Relic RF)
A5: King Dangun Statue | B5: S | C5: FTH | D5: 20 | E5: 20 | K5: Fragment Crafting (15.1%), Lottery Machine #1 (0.81%), Wishing (0.81%), Koryeo Treasure Map (5%), Relic Forge (90 Relic RF), Museum Value Pack I ($14.99)
A6: Sunflowers | B6: SS | C6: ART | D6: 22 | K6: Lottery Machine #1 (0.12%), Wishing (0.1%), Fungus Chest (1%), Grandmaster Scrolls (1%), Relic Forge (100 Relic RF)
A7: The Song of Roland | B7: SS | C7: CIV | F7: 22 | G7: 20 | K7: Fragment Crafting (5.5%), Lottery Machine #1 (0.24%), Wishing (0.2%), Master Scroll (1.9%), Grandmaster Scroll (2.1%), CIV Master Scroll (10.2%)
A8: Haulers on Volga | B8: AAA | C8: ART | H8: 18 | I8: 14 | K8: Fragment Crafting (1.6%), Lottery Machine #1 (0.03%), Wishing (0.14%), Relic Forge (Relic RF 80), Indigent Nobleman (120K B-tads)
A9: Crystal Piano | B9: AAA | C9: CIV | D9: 18 | E9: 14 | F9: 18 | K9: Fragment Crafting (1.5%), Lottery Machine #1 (0.03%), Wishing (0.14%), Relic Forge (80 Relic RF), Indigent Nobleman (120K B-tads)
A10: Peacock Throne | B10: AAA | C10: ART | D10: 5 | E10: 5 | K10: Supreme Relic
A11: Universe Bowl | B11: Blue | C11: ART | F11: 10 | G11: 10 | K11: Lottery Machine #1 (0.07%), Wishing (3%), Fungus Chest (2%), Trainee Scrolls (1%)
A12: Rainbow Tadpole | B12: Green | C12: FTH | H12: 6 | K12: Tadpole pond after acquiring alchemy furnace
A13: Gold Fishing Rod | B13: Green | C13: FAME | H13: 6 | K13: Defeat Assassin Eve (Racoon Storyline)
A14: B-Tadpole XL | B14: Green | C14: ART | D14: 6 | K14: Intercept Hitman No.16
A15: Electric Fishing Net | B15: Green | C15: TECH | F15: 6 | K15: Bought from the Salesman
A16: MAX INDIVIDUAL RELICS | D16: =SUM(D3:E15) | F16: =SUM(F3:G15) | H16: =SUM(H3:I15)
A18: PARTNER
A19: Kim Chi-yum | D19: 9 | K19: lv30
A21: ORGAN
A22: Warp Horn | D22: 10 | F22: 10 | K22: lv20
A23: Alveolus of Gaia | D23: 20 | F23: 20 | K23: lv40
A24: MAX ORGAN | D24: =sum(D22:D23) | F24: =sum(F22:F23) | H24: =sum(H22:H23)
A26: BUBBLE FRAMES
A27: Whale Power III | D27: 12 | K27: 5M W-tads Spent
A29: COLLECTORS TALENTS
A30: Tadpole Raising | D30: 25 | F30: 25 | K30: 10 Purple Talent Points
A32: ROBOTS
A33: Pure White Doc | D33: 3 | K33: Wormhole Refiner (0.03%)
A35: ROCKET UPGRADES
A36: Eternal Hall | D36: 10 | F36: 10 | K36: Lv5
A38: AVATARS
A39: Mirage Avatar I Bonus | D39: 20 | F39: 40
A41: STAMPS
A42: Golden Wheat | B42: SSS | C42: ART | D42: 30 | H42: 30 | J42: 15 | K42: Wish Pack, Lottery Machine #1 (0.09%), Wishing (0.08%), Yamato Treasure Maps (0.01%), Grandmaster Scrolls (0.81%), Relic Forge (120 Relic RF)
A43: Alexander The Great | B43: SSS | C43: ART | D43: 30 | F43: 30 | J43: 15 | K43: Lucky Stars Event Reward
A44: Swan Lake | B44: SS | C44: ART | D44: 30 | J44: 15 | K44: Lottery Machine #1 (0.12%), Wishing (0.1%), Grandmaster Scrolls (1%), Relic Forge (100 Relic RF)
A45: Lotus Chalice | B45: SSS | C45: ART | D45: 30 | F45: 30 | H45: 30 | K45: Wish Pack, Lottery Machine #1 (0.09%), Wishing (0.08%), Kemetic Treasure Chests (0.01%), Grandmaster Scrolls (0.81%), Relic Forge (120 Relic RF)
A46: Ship in a Bottle | B46: SS | C46: ART | D46: 30 | H46: 30 | K46: Fragment Crafting (4%), Lottery Machine #1 (0.18%), Wishing (0.15%), Grandmaster Scrolls (1.6%)
A47: Parthenon Marbles | B47: SS | C47: ART | D47: 30 | K47: Hellas Costume Lottery Reward
A48: Sunflowers | B48: SS | C48: ART | H48: 30 | J48: 15 | K48: Lottery Machine #1 (0.12%), Wishing (0.1%), Fungus Chest (1%), Grandmaster Scrolls (1%), Relic Forge (100 Relic RF)
...

Sheet Fungus Farm
A1: Name | B1: Rarity | C1: Type | D1: Base Output | E1: Awakening Output | F1: Base Cap | G1: Awakening Cap | H1: Wonder Fungus | I1: Awakening Wonder Fungus | J1: AFFECT Boost | K1: Source
A2: INDIVIDUAL RELICS
A3: The Last Supper | B3: S | C3: ART | D3: 20 | E3: 20 | F3: 20 | K3: Fragment Crafting (18.1%), Lottery Machine #1 (0.81%), Wishing (0.68%), Relic Forge (90 Relic RF)
A4: Sunflowers | B4: SS | C4: ART | D4: 22 | E4: 20 | K4: Lottery Machine #1 (0.12%), Wishing (0.1%), Fungus Chest (1%), Grandmaster Scrolls (1%), Relic Forge (100 Relic RF)
A5: Golden Wheat | B5: SSS | C5: ART | D5: 24 | K5: Wish Pack, Lottery Machine #1 (0.09%), Wishing (0.08%), Yamato Treasure Maps (0.01%), Grandmaster Scrolls (0.81%), Relic Forge (120 Relic RF)
A6: Edict of Milan | B6: AAA | C6: FAME | H6: 18 | I6: 14 | K6: Fragment Crafting (1.6%), Lottery Machine #1 (0.03%), Wishing (0.14%), Relic Forge (80 Relic RF)
A7: The Goodbye Kiss | B7: AAA | C7: ART | H7: 9 | I7: 7 | K7: Lottery Box Relic #2
A8: Frigga's Wheel | B8: AAA | C8: FTH | D8: 14 | F8: 14 | G8: 14 | K8: Fragment Crafting (30.8%), Lottery Machine #1 (0.66%), Wishing (2.8%), Expert Scrolls (7.6%)
A9: Peacock Throne | B9: AAA | C9: ART | D9: 5 | E9: 5 | K9: Supreme Relic
A10: Leo's Plant | B10: Blue | C10: CIV | D10: 10 | E10: 10 | K10: Lottery Machine #1 (0.36%), Wishing (10.3%), Fungus Chest (2%), Trainee Scrolls (5%)
A11: Portland Vase | B11: Blue | C11: ART | F11: 10 | G11: 10 | K11: Lottery Machine #1 (0.03%), Wishing (1.2%), Fungus Chest (2%)
A12: Earthworm Codex | B12: Green | C12: FAME | H12: 6 | K12: Earth Worm Reactor (Species War Cabin) Reward
A13: Isle Turnip | B13: Green | C13: CIV | H13: 6 | K13: Racoon Storyline
A14: Mutant Fungus | B14: Green | C14: FTH | H14: 6 | K14: Buried in the Farm
A15: Shinkage Ryu: Shift | B15: Green | C15: TECH | D15: 6 | K15: Yamato Domain
A16: MAX INDIVIDUAL RELICS | D16: =sum(D3:E15) | F16: =sum(F3:G15) | H16: =sum(H3:I15)
A18: ORGAN
A19: Warp Horn | D19: 10 | F19: 10 | K19: lv20
A20: Alveolus of Gaia | D20: 20 | F20: 20 | K20: lv40
A21: MAX ORGAN | D21: =sum(D19:D20) | F21: =sum(F19:F20) | H21: =sum(H19:H20)
A23: BUBBLE FRAMES
A24: Whale Power III | D24: 12 | K24: 5M W-tads Spent
A26: COLLECTORS TALENTS
A27: Fungus Growth | D27: 25 | F27: 25 | K27: 10 Blue Talent Points
A29: ROCKET UPGRADES
A30: Eternal Hall | D30: 10 | F30: 10 | K30: Lv5
A32: AVATARS
A33: Mirage Avatar I Bonus | D33: 20 | F33: 40
A35: STAMPS
A36: 1001 Nights | B36: SSS | C36: CIV | D36: 30 | H36: 30 | J36: 15 | K36: Wish Pack, Lottery Machine #1 (0.09%), Wishing (0.08%), Bharata Treasure Maps(%), Grandmaster Scrolls (0.81%), Relic Forge (120 Relic RF)
A37: Creation of Adam | B37: SSS | C37: CIV | F37: 30 | H37: 30 | J37: 15 | K37: Lottery Machine #1 (0.09%), Wishing (0.08%), Grandmaster Scrolls (0.77%)
A38: Cyrus Cylinder | B38: SSS | C38: CIV | D38: 30 | F38: 30 | J38: 15 | K38: Lottery Machine #2 (?%)
A39: The Song of Roland | B39: SS | C39: CIV | D39: 30 | F39: 30 | K39: Fragment Crafting (5.5%), Lottery Machine #1 (0.24%), Wishing (0.2%), Master Scroll (1.9%), Grandmaster Scroll (2.1%), CIV Master Scroll (10.2%)
A40: Das Kapital | B40: SS | C40: CIV | D40: 30 | F40: 30 | K40: Lottery Machine #1 (0.12%), Wishing (0.1%), Britland Treasure Maps (5%), Grandmaster Scrolls (1%), Relic Forge (100 Relic RF), beat Mr. Raccoon in combat
A41: Plato's Republic | B41: SS | C41: CIV | H41: 30 | J41: 15 | K41: Lottery Machine #1 (0.12%), Wishing (0.1%), Grandmaster Scrolls (1%), Relic Forge (100 Relic RF), Home Value Pack III ($14.99)
A42: Pride & Prejudice | B42: S | C42: CIV | H42: 30 | K42: Lottery Machine #2 (1.59%)
A43: Julian Calendar | B43: SS | C43: CIV | F43: 30 | K43: Fragment Crafting (5.5%), Lottery Machine #1 (0.24%), Wishing (0.2%), Master Scrolls (1.9%), Grandmaster Scrolls (2.1%), CIV Master Scrolls (10.2%)
A44: Boat of St. Peter | B44: SS | C44: FTH | H44: 30 | K44: Fragment Crafting (4%), Lottery Machine #1 (0.18%), Wishing (0.15%), Grandmaster Scrolls (1.6%)
A45: Golden Scarab | B45: S | C45: FTH | H45: 30 | K45: Fragment Crafting (15.1%), Lottery Machine #1 (0.81%), Wishing (0.53%), Kemetic Treasure Maps (5%), Master Scrolls (6.5%), FTH Master Scrolls (31.5%), Relic Forge (90 Relic RF)
A46: Holy Loaves | B46: SS | C46: FTH | D46: 30 | K46: Lottery Machine #1 (0.12%), Wishing (0.08%), Evolution Chest (1%), Grandmaster Scrolls (1%), Relic Forge (100 Relic RF)
...

Sheet Time Machine
A1: Name | B1: Rarity | C1: Type | D1: Base Output | E1: Awakening Output | F1: Base Cap | G1: Awakening Cap | H1: Time Chest | I1: Awakening Time Chest | J1: AFFECT Boost | K1: Source
A2: INDIVIDUAL RELICS
A3: Sputnik 1 | B3: SS | C3: TECH | D3: 22 | F3: 22 | H3: 22 | I3: 20 | K3: Fragment Crafting (3.9%), Lottery Machine #1 (0.18%), Wishing (0.14%), Club Chest (1%), Grandmaster Scrolls (1.6%)
A4: Artificial Black Hole | B4: SSS | C4: TECH | D4: 24 | E4: 20 | K4: Wish Box, Lottery Machine #1 (0.09%), Wishing (0.07%), Demon God Chest (0.1%), Grandmaster Scrolls (0.81%), Relic Forge (120 Relic RF), Nebula Chest (0.01%)
A5: Golden Wheat | B5: SSS | C5: ART | D5: 24 | K5: Wish Pack, Lottery Machine #1 (0.09%), Wishing (0.08%), Yamato Treasure Maps (0.01%), Grandmaster Scrolls (0.81%), Relic Forge (120 Relic RF)
A6: Morse's Telegraph | B6: SS | C6: TECH | D6: 22 | K6: Fragment Crafting (5.2%), Lottery Machine #1 (0.24%), Wishing (0.19%), Tool Chest (1%), Master Scrolls (1.9%), Grandmaster Scrolls (2.1%), TECH Master Scrolls (9.2%)
A7: Notre Dame Bell | B7: S | C7: CIV | F7: 20 | G7: 20 | K7: Fragment Crafting (18.8%), Lottery Machine #1 (0.81%), Wishing (0.69%), Relic Forge (90 Relic RF)
A8: Bell's Telephone | B8: AAA | C8: TECH | H8: 18 | I8: 14 | K8: Fragment Crafting (1.6%), Lottery Machine #1 (0.03%), Wishes (0.14%), Relic Forge (80 Relic RF)
A9: Kapa's Camera | B9: AAA | C9: CIV | D9: 18 | E9: 14 | F9: 18 | K9: Fragment Crafting (1.5%), Lottery Machine #1 (0.03%), Wishing (0.14%), Relic Forge (80 Relic RF)
A10: Yuan Calendar | B10: AAA | C10: TECH | H10: 16 | K10: Fragment Crafting (3.9%), Lottery Machine #1 (0.08%), Wishing (0.36%), Koryeon Treasure Maps (10%), Expert Scrolls (0.95%)
A11: Keyhole Satellite | B11: AAA | C11: TECH | E11: 15 | F11: 15 | K11: Fragment Crafting (1.6%), Lottery Machine #1 (0.03%), Wishing (0.14%), Relic Forge (80 Relic RF), Nebula Chest (1.5%)
A12: Peacock Throne | B12: AAA | C12: ART | D12: 5 | E12: 5 | K12: Supreme Relic
A13: Peacock Clock | B13: Blue | C13: ART | D13: 10 | E13: 10 | K13: Lottery Machine #1 (0.03%), Wishing (1.2%), Bharata Treasure Maps (%), Time Chest (2%)
A14: Cuckoo Clock | B14: Blue | C14: ART | F14: 10 | G14: 10 | K14: Lottery Machine #1 (0.07%), Wishing (3%), Time Chest (2%), Trainee Scrolls (1%)
A15: Sands of Time | B15: Green | C15: ART | H15: 6 | K15: Fissure Floor 1968
A16: Nuclear Fusion Battery | B16: Green | C16: TECH | D16: 6 | K16: Robot Guard
A17: Blower | B17: Green | C17: TECH | D17: 6 | K17: Defeat Pepper the Butcher
A18: MAX INDIVIDUAL RELICS | D18: =SUM(D4:E17) | F18: =SUM(F4:G17) | H18: =SUM(H4:I17)
A20: PARTNER
A21: Lee Gi-na | D21: 30 | K21: lv30
A23: COLLECTORS TALENTS
A24: Dimension Keeper | D24: 25 | F24: 25 | K24: 10 Orange Talent Points
A26: ROBOTS
A27: Hello Boxer | D27: 3 | K27: Wormhole Refiner (0.03%)
A29: INTEL
A30: Cathay | D30: 10
A32: BUBBLE FRAMES
A33: Whale Power III | D33: 12 | K33: 5M W-tads Spent
A35: ORGAN
A36: Alveolus of Gaia | D36: 20 | F36: 20 | K36: lv40
A37: Warp Horn | D37: 10 | F37: 10 | K37: lv20
A38: Universe Energy Cube | D38: 30 | K38: lv30
A39: MAX ORGAN | D39: =sum(D36:D38) | F39: =sum(F36:F38) | H39: =sum(H36:H38)
A41: ROCKET UPGRADES
A42: Eternal Hall | D42: 10 | F42: 10 | K42: Lv5
A44: AVATARS
A45: Mirage Avatar I Bonus | D45: 20 | F45: 40
A47: STAMPS
A48: Particle Collider | B48: SSS | C48: TECH | D48: 30 | H48: 30 | J48: 15 | K48: Wish Box, Lottery Machine #1 (0.09%), Wishing (0.07%), Tool Chest (0.01%), Grandmaster Scrolls (0.81%), Relic Forge (120 Relic RF)
A49: Quantum Radio | B49: SSS | C49: TECH | D49: 30 | F49: 30 | J49: 15 | K49: Super Species Chest (0.03%)
...

Sheet Lumber Camp
A1: Name | B1: Rarity | C1: Type | D1: Base Output | E1: Awakening Output | F1: Base Cap | G1: Awakening Cap | H1: Ancient Lumber | I1: Awakening Ancient Lumber | J1: AFFECT Boost | K1: Source
A2: INDIVIDUAL RELICS
A3: Julian Calendar | B3: SS | C3: CIV | D3: 22 | E3: 20 | F3: 22 | K3: Fragment Crafting (5.5%), Lottery Machine #1 (0.24%), Wishing (0.2%), Master Scrolls (1.9%), Grandmaster Scrolls (2.1%), CIV Master Scrolls (10.2%)
A4: Encyclopedia | B4: SSS | C4: FAME | D4: 24 | E4: 20 | K4: Wish Box, Lottery Machine #1 (0.09%), Wishing (0.09%), Grandmaster Scrolls (0.81%), Relic Forge (120 Relic RF)
A5: Das Kapital | B5: SS | C5: CIV | D5: 22 | F5: 22 | K5: Lottery Machine #1 (0.12%), Wishing (0.1%), Britland Treasure Maps (5%), Grandmaster Scrolls (1%), Relic Forge (100 Relic RF), beat Mr. Raccoon in combat
A6: Plato's Republic | B6: SS | C6: CIV | D6: 22 | K6: Lottery Machine #1 (0.12%), Wishing (0.1%), Grandmaster Scrolls (1%), Relic Forge (100 Relic RF)
A7: King Dangun Statue | B7: S | C7: FTH | D7: 20 | K7: Fragment Crafting (15.1%), Lottery Machine #1 (0.81%), Wishing (0.81%), Koryeo Treasure Map (5%), Relic Forge (90 Relic RF), Museum Value Pack I ($14.99)
A8: The Decameron | B8: AA | C8: CIV | D8: 16 | E8: 14 | F8: 16 | K8: Fragment Crafting (3.7%), Lottery Machine #1 (0.8%), Wishing (0.34%), Britland Treasure Maps (10%), Expert Scrolls (0.95%)
A9: Cavendish's Scale | B9: AAA | C9: TECH | H9: 18 | I9: 14 | K9: Fragment Crafting (1.6%), Lottery Machine #1 (0.03%), Wishing (0.14%), Relic Forge (80 Relic RF)
A10: Peacock Throne | B10: AAA | C10: ART | D10: 5 | E10: 5 | K10: Supreme Relic
A11: Klein Bottle | B11: Blue | C11: TECH | D11: 10 | E11: 10 | K11: Lottery Machine #1 (0.07%), Wishing (2.6%), Novice Scrolls (1%)
A12: Campbell's Sextant | B12: Blue | C12: TECH | F12: 10 | G12: 10 | K12: Lottery Machine #1 (0.7%), Wishing (2.6%), Tool Chest (2%), Novice Scrolls (1%)
A13: MAX INDIVIDUAL RELICS | D13: =SUM(D3:E12) | F13: =SUM(F3:G12) | H13: =SUM(H3:I12)
A15: PARTNER
A16: Advisor Zhuge | D16: 30 | K16: lv30
A18: COLLECTORS TALENTS
A19: Civil Engineering | D19: 25 | F19: 25 | K19: 10 Blue Talent Points
A21: ROBOTS
A22: Craftsman III | D22: 3 | K22: Wormhole Refiner (0.03%)
A24: ORGAN
A25: Warp Horn | D25: 10 | F25: 10 | K25: lv20
A26: Alveolus of Gaia | D26: 20 | F26: 20 | K26: lv40
A27: MAX ORGAN | D27: =SUM(D25:D26) | F27: =SUM(F25:F26) | H27: =SUM(H25:H26)
A29: INTEL
A30: Cathay | D30: 10
A32: ROCKET UPGRADES
A33: Eternal Hall | D33: 10 | F33: 10 | K33: Lv5
A35: AVATARS
A36: Mirage Avatar I Bonus | D36: 20 | F36: 40
A38: STAMPS
A39: Turing Award | B39: SSS | C39: FAME | D39: 30 | H39: 30 | J39: 15 | K39: Daily Pack Relic #26
A40: Prometheus Torch | B40: SSS | C40: FAME | D40: 30 | F40: 30 | H40: 30 | K40: Lottery Machine #1 (0.09%), Wishing (0.09%), Hellas Treasure Map, Grandmaster Scrolls (0.81%), Relic Forge (120 Relic RF)
A41: Nobel's Will | B41: SSS | C41: FAME | D41: 30 | F41: 30 | J41: 15 | K41: Lottery Machine #1 (0.09%), Wishing (0.08%), Grandmaster Scrolls (0.79%), Lottery Event 9/22/2023-9/28/2023
A42: Hammurabi Code | B42: SS | C42: FAME | H42: 30 | J42: 15 | K42: Fragment Crafting (4.6%), Lottery Machine #1 (0.18%), Wishing (0.17%), Demon God Chest (5%), Grandmaster Scrolls (1.6%)
A43: Zircon of Jack Hills | B43: SS | C43: FAME | H43: 30 | K43: Lottery Machine #2 (0.47%)
A44: Ape's Footprint Fossil | B44: SS | C44: FAME | D44: 30 | F44: 30 | K44: Super Species Chest (2.4%)
A45: Stockholm Declaration | B45: SS | C45: FAME | D45: 30 | F45: 30 | K45: Lottery Machine #2 (0.47%), Indigent Nobleman (570K B-tads)
A46: Tetromino | B46: S | C46: FAME | D46: 30 | K46: Fragment Crafting (20.7%), Lottery Machine #1 (0.81%), Wishing (0.75%), Master Scrolls (6.5%), FAME Master Scrolls (31.5%), Relic Forge (90 Relic RF)
A47: Proclamation 95 | B47: S | C47: FAME | J47: 15 | K47: Fragment Crafting (0.61), Lottery Machine #1 (0.24%), Wishing (0.22%), Master Scrolls (0.19%), Grandmaster Scrolls (2.1%), FAME Master Scroll (9.2%)
A48: Golden Finger | B48: S | C48: FTH | D48: 30 | K48: Fragment Crafting (15.1%), Lottery Machine #1 (0.81%), Wishing (0.53%), Master Scrolls (6.5%), FTH Master Scrolls (31.5%), Relic Forge (90 Relic RF), Rock in front of garage 999 taps, give Peter Jr. 42 0-star reviews in the same conversation
...

Sheet Quarry
A1: Name | B1: Rarity | C1: Type | D1: Base Output | E1: Awakening Output | F1: Base Cap | G1: Awakening Cap | H1: Ancient Fossil | I1: Awakening Ancient Fossil | J1: AFFECT Boost | K1: Source
A2: INDIVIDUAL RELICS
A3: Cairo Declaration | B3: SS | C3: FAME | D3: 22 | F3: 22 | H3: 22 | I3: 20 | K3: Fragment Crafting (4.6%), Lottery Machine (0.18%), Wishing (0.17%), Grandmaster Scrolls (1.6%)
A4: David | B4: SS | C4: ART | D4: 22 | E4: 20 | F4: 22 | K4: Fragment Crafting (4%), Lottery Machine (0.18%), Wishing (0.15%), Demon God Chest (5%), Grandmaster Scrolls (1.6%)
A5: Plato's Republic | B5: SS | C5: CIV | D5: 22 | E5: 20 | K5: Lottery Machine (0.12%), Wishing (0.1%), Grandmaster Scrolls (1%), Relic Forge (100 Relic RF)
A6: King Dangun Statue | B6: S | C6: FTH | D6: 20 | K6: Fragment Crafting (15.1%), Lottery Machine (0.81%), Wishing (0.81%), Koryeo Treasure Map (5%), Relic Forge (90 Relic RF), Museum Value Pack I ($14.99)
A7: Galileo's Ball | B7: AAA | C7: FAME | H7: 18 | I7: 14 | K7: Fragment Crafting (1.6%), Lottery Machine (0.03%), Wishing (0.14%), Relic Forge (80 Relic RF)
A8: Phoenician Tablet | B8: AA | C8: CIV | D8: 16 | E8: 14 | F8: 16 | K8: Fragment Crafting (3.7%), Lottery Machine (0.8%), Wishing (0.34%), Kemetic Treasure Maps (10%), Expert Scrolls (0.95%)
A9: Peacock Throne | B9: AAA | C9: ART | D9: 5 | E9: 5 | K9: Supreme Relic
A10: Chronometer | B10: Blue | C10: TECH | D10: 10 | E10: 10 | K10: Lottery Machine (0.03%), Wishing (1.1%), Tool Chest (2%)
A11: Costa Rica Stone | B11: Blue | C11: FAME | F11: 10 | G11: 10 | K11: Lottery Machine (0.36%), Wishing (15.5%), Novice Scrolls (5%)
A12: Birdie | B12: Green | C12: FTH | D12: 6 | K12: Defeat Ronin Katsura
A13: Ancient Snail Fossil | B13: Green | C13: CIV | H13: 6 | K13: Zuckie's Ad Events
A14: MAX INDIVIDUAL RELICS | D14: =sum(D3:E13) | F14: =sum(F3:G13) | H14: =sum(H3:I13)
A16: PARTNER
A17: Taoist Yu Ji | D17: 30 | K17: lv30
A19: COLLECTORS TALENTS
A20: Civil Engineering | D20: 25 | F20: 25 | K20: 10 Blue Talent Points
A22: ROBOTS
A23: Surprise | D23: 3 | K23: Wormhole Refiner (0.03%)
A25: ORGAN
A26: Warp Horn | D26: 10 | F26: 10 | K26: lv20
A27: Alveolus of Gaia | D27: 20 | F27: 20 | K27: lv40
A28: MAX ORGAN | D28: =sum(D26:D27) | F28: =sum(F26:F27) | H28: =sum(H26:H27)
A30: INTEL
A31: Cathay | D31: 10
A33: ROCKET UPGRADES
A34: Eternal Hall | D34: 10 | F34: 10 | K34: Lv5
A36: AVATARS
A37: Mirage Avatar I Bonus | D37: 20 | F37: 40
A39: STAMPS
A40: Gaea's Hand | B40: SSS | C40: FTH | D40: 30 | F40: 30 | H40: 30 | K40: Wish Pack, Lottery Machine (0.09%), Wishing (0.06%), Grandmaster Scrolls (0.81%), Relic Forge (120 Relic RF)
A41: Aladdin Lamp | B41: SS | C41: FTH | D41: 30 | J41: 15 | K41: Lottery Machine (0.12%), Wishing (0.08%), Grandmaster Scrolls (1%), Relic Forge (100 Relic RF), Altar Value Pack II ($49.99)
A42: Mahakala Scroll | B42: SSS | C42: FTH | F42: 30 | H42: 30 | J42: 15 | K42: Jinx Points Bonus Reward
A43: The Argo | B43: SSS | C43: FTH | F43: 30 | H43: 30 | J43: 15 | K43: Lottery Machine (0.09%), Summer Festival Sept. 1-15, 2023
A44: Golden Finger | B44: S | C44: FTH | D44: 30 | K44: Fragment Crafting (15.1%), Lottery Machine (0.81%), Wishing (0.53%), Master Scrolls (6.5%), FTH Master Scrolls (31.5%), Relic Forge (90 Relic RF)
A45: Shroud of Turin | B45: S | C45: FTH | H45: 30 | K45: Fragment Crafting (15.1%), Lottery Machine (0.81%), Wishing (0.53%), Relic Forge (90 Relic RF)
A46: Ark of the Covenant | B46: S | C46: FTH | H46: 30 | K46: Fragment Crafting (15.1%), Lottery Machine (0.81%), Wishing (0.53%), Relic Forge (90 Relic RF)
A47: 3-Faced Statue | B47: S | C47: FTH | J47: 15 | K47: Fragment Crafting (4.4%), Lottery Machine (0.24%), Wishing (0.16%), Demon God Chest (5%), Master Scrolls (1.9%), Grandmaster Scrolls (2.1%), FTH Master Scrolls (9.2%), Indigent Nobleman (570K B-tads)
A48: The Key of Solomon | B48: SS | C48: FTH | F48: 30 | J48: 15 | K48: T7f Demon Gene Research
...

Sheet Quantum Amp
A1: Name | B1: Rarity | C1: Type | D1: Base Output | E1: Awakening Output | F1: Base Cap | G1: Awakening Cap | H1: Nebula Chest | I1: Awakening Nebula Chest | J1: AFFECT Boost | K1: Source
A2: INDIVIDUAL RELICS
A3: Olympic Torch | B3: SSS | C3: FAME | D3: 7.2 | E3: 6 | K3: Wish Box Album Relic #3
A4: Outer Space Treaty | B4: SSS | C4: FAME | D4: 7.2 | E4: 6 | K4: Star Chart Shop
A5: Great Mogul Diamond | B5: SSS | C5: ART | D5: 7.2 | E5: 6 | K5: Badge Shop
A6: Narmer Palette | B6: SSS | C6: CIV | H6: 7.2 | I6: 6 | K6: Traveler's Pack Reward #3
A7: Scales of Astraea | B7: SSS | C7: FTH | F7: 12 | G7: 10 | K7: Star Chart Shop
A8: Indus Seal | B8: AAA | C8: CIV | F8: 9 | G8: 7 | H8: 5.4 | K8: Indigent Nobleman (210K B-tads)
A9: Djinn Theory | B9: AAA | C9: CIV | F9: 9 | G9: 7 | K9: Lottery Box Relic #11
A10: Mesopotamian Wheel | B10: AAA | C10: FAME | D10: 5.4 | K10: Lottery Box Relic #17
A11: Biography of Great Artists | B11: AAA | C11: FAME | D11: 5.4 | E11: 4.2 | K11: Lottery Box Relic #13
A12: Nishijin Fabric | B12: AAA | C12: ART | D12: 5.4 | E12: 4.2 | K12: Lottery Box Relic #8
A13: Peacock Throne | B13: AAA | C13: ART | D13: 5 | E13: 5 | K13: Supreme Relic Reward
A14: V8 Engine | B14: AAA | C14: TECH | D14: 3.6 | E14: 2.8 | K14: Time Beacon Reward
A15: The Fifer | B15: AAA | C15: ART | F15: 9 | G15: 7 | K15: Lottery Box Relic #6
A16: MAX INDIVIDUAL RELICS | D16: =sum(D3:E15) | F16: =sum(F3:G15) | H16: =sum(H3:I15)
A18: ORGAN
A19: Warp Horn | D19: 10 | F19: 10 | K19: lv20
A20: Alveolus of Gaia | D20: 20 | F20: 20 | K20: lv40
A21: MAX ORGAN | D21: =sum(D19:D20) | F21: =sum(F19:F20) | H21: =sum(H19:H20)
A23: ROCKET UPGRADES
A24: Eternal Hall | D24: 10 | F24: 10 | K24: Lv5
A26: AVATARS
A27: Mirage Avatar I Bonus | D27: 20 | F27: 40
A29: STAMPS
A30: Natural History | B30: SSS | C30: FAME | D30: 15 | H30: 15 | J30: 15 | K30: Lottery Machine #3 (?%)
A31: Outer Space Treaty | B31: SSS | C31: FAME | D31: 15 | F31: 30 | J31: 15 | K31: Star Chart Shop
A32: Ram in a Thicket | B32: SSS | C32: ART | D32: 15 | F32: 30 | J32: 15 | K32: Daily Pack Relic #43
A33: Constellations | B33: SSS | C33: ART | F33: 30 | H33: 15 | J33: 15 | K33: Star Chart Shop
A34: Scales of Astraea | B34: SSS | C34: FTH | D34: 15 | H34: 15 | J34: 15 | K34: Star Chart Shop
A35: Ra's Solar Barque | B35: SSS | C35: FTH | D35: 15 | F35: 30 | J35: 15 | K35: Traveler's Pack #14
A36: Anna Karenina | B36: SSS | C36: CIV | D36: 15 | H36: 15 | J36: 15 | K36: Daily Pack Relic #49
A37: Hevelius Chart | B37: SSS | C37: CIV | D37: 15 | F37: 30 | J37: 15 | K37: Star Chart Shop
A38: Messier Catalogue | B38: SSS | C38: TECH | D38: 15 | F38: 30 | H38: 15 | K38: Star Chart Shop
A39: Infin. Improb. Eng. | B39: SSS | C39: TECH | D39: 15 | F39: 30 | J39: 15 | K39: Daily Pack Relic #51
A40: MAX QUANTUM AMP STAMPS | D40: =D30+D32+D34+D36+D38 | F40: =F30+F32+F34+F36+F38 | H40: =H30+H32+H34+H36+H38 | J40: =J30+J32+J34+J36+J38
A42: RESONANCE
A43: ORANGE
A44: Output | D44: 7
A45: Hevelius Chart | B45: SSS | C45: CIV | K45: Star Chart Shop
...

Sheet Compass
A1: Dung Beetle | D1: Main AFFCT | E1: Stamp 1 | F1: Stamp 2 | G1: Stamp 3 | H1: HP | I1: ATK | J1: RUSH | K1: DEF | L1: CRIT | M1: CRIT DMG | N1: DMG | O1: DMG Reduc | P1: Hero DMG | Q1: ELMT DMG | R1: AFFCT | S1: Source | Y1: AFFCT | Z1: FAME | AA1: Non-FAME
A2: INDIVIDUAL RELICS | Y2: 49 | Z2: 0.5 | AA2: 2.4
A3: Celestial Mechanics | B3: SSS | C3: FAME | D3: 109 | E3: All ELMT DMG +15 | F3: RUSH +9% | G3: CRIT DMG +9% | J3: 9 | M3: 9 | Q3: 75 | S3: Lottery Machine No. 3 (0.12%) | Y3: 57 | Z3: 0.6 | AA3: 2.8
A4: Antarctic Treaty | B4: SSS | C4: FAME | D4: 108 | E4: Water DMG +60 | F4: FAME +15 | G4: CRIT DMG +9% | M4: 9 | Q4: 60 | R4: 15 | S4: Lottery Machine No. 2 (0.11%) | Y4: 66 | Z4: 0.7 | AA4: 3.3
A5: The Prince | B5: SSS | C5: FAME | D5: 106 | E5: ATK +6% | F5: FAME +15 | G5: CRIT DMG +6% | I5: 6 | M5: 6 | R5: 15 | S5: Lottery Machine No. 2 (0.11%) | Y5: 83 | Z5: 1 | AA5: 4.1
A6: Cross of Lorraine | B6: SS | C6: FAME | D6: 104 | E6: FAME +15 | F6: ATK +6% | I6: 6 | R6: 15 | S6: Lottery Machine No. 2 (?%) | Y6: 84 | Z6: 1 | AA6: 4.2
A7: Two-headed Serpent | B7: SSS | C7: ART | D7: 106 | E7: Hero DMG +6% | F7: Wind DMG +30 | G7: ATK +9% | I7: 9 | P7: 6 | Q7: 30 | S7: Lottery Machine No. 2 (0.11%), Relic Forge (120 RF) | Y7: 85 | Z7: 1 | AA7: 4.2
A8: Ivan the Terrible | B8: SSS | C8: ART | D8: 109 | E8: Wind DMG +60 | F8: DEF +9% | G8: RUSH +9% | J8: 9 | K8: 9 | Q8: 60 | S8: Lottery Machine No. 3 (0.12%) | Y8: 86 | Z8: 1 | AA8: 4.3
A9: Seated Voltaire | B9: SSS | C9: ART | D9: 106 | E9: DEF +6% | F9: ART +15 | G9: Wind DMG +30 | K9: 6 | Q9: 30 | R9: 15 | S9: Wish Box Relic Album #1 | Y9: 87 | Z9: 1 | AA9: 4.3
A10: Woman at Her Toilette | B10: SSS | C10: ART | D10: 109 | E10: ATK +6% | F10: RUSH +6% | G10: ART +15 | I10: 6 | J10: 6 | R10: 15 | S10: Minion Skin Lottery | Y10: 88 | Z10: 1.1 | AA10: 4.4
A11: Vedas | B11: SSS | C11: FTH | D11: 108 | E11: DEF +9% | F11: FTH +15 | G11: CRIT +9% | K11: 9 | L11: 9 | R11: 15 | S11: Lottery Machine No. 2 (0.11%) | Y11: 89 | Z11: 1.1 | AA11: 4.4
A12: Akashic Records | B12: SSS | C12: FTH | D12: 106 | E12: FTH +15 | F12: HP +9% | G12: DMG REDUC +6% | H12: 9 | O12: 6 | R12: 15 | S12: Lottery Machine No. 3 (0.12%) | Y12: 90 | Z12: 1.1 | AA12: 4.5
A13: The Myth of Etana | B13: S | C13: FTH | D13: 100 | E13: CRIT +9% | L13: 9 | S13: Lottery Machine No. 3 (1.63%) | Y13: 91 | Z13: 1.1 | AA13: 4.5
A14: Enuma Elish | B14: SSS | C14: FTH | D14: 107 | E14: FTH +15 | F14: ATK +6% | G14: RUSH +6% | I14: 6 | J14: 6 | R14: 15 | S14: Lottery Machine No. 2 (0.11%) | Y14: 92 | Z14: 1.1 | AA14: 4.6
A15: Beowulf | B15: SSS | C15: CIV | D15: 107 | E15: CIV +15 | F15: Fire DMG +60 | G15: Fire DMG +30 | Q15: 90 | R15: 15 | S15: Lottery Machine No. 2 (0.11%) | Y15: 93 | Z15: 1.1 | AA15: 4.6
A16: Of Human Bondage | B16: SSS | C16: CIV | D16: 109 | E16: CRIT +9% | F16: Hero DMG +6% | G16: Earth RES +60 | L16: 9 | P16: 6 | S16: Daily Pack #??
A17: Don Juan | B17: SSS | C17: CIV | D17: 106 | E17: CIV +15 | F17: HP +9% | G17: ATK +9% | H17: 9 | I17: 9 | R17: 15 | S17: Daily Pack #40 | Y17: 94 | Z17: 1.1 | AA17: 4.7
A18: Frederick Portrait | B18: SSS | C18: CIV | D18: 106 | E18: HP +9% | F18: RUSH +9% | G18: Water DMG +60 | H18: 9 | J18: 9 | Q18: 60 | S18: Unknown | Y18: 95 | Z18: 1.1 | AA18: 4.7
A19: Harem Wall Painting | B19: SS | C19: CIV | D19: 106 | E19: CIV +15 | F19: RUSH +6% | J19: 6 | R19: 15 | S19: Lottery Machine No. 2 (?%) | Y19: 96 | Z19: 1.2 | AA19: 4.8
A20: Volsunga Saga | B20: SSS | C20: CIV | D20: 109 | E20: CIV +15 | F20: ATK +9% | G20: DEF +9% | I20: 9 | K20: 9 | R20: 15 | S20: Gold Pack #6 | Y20: 97 | Z20: 1.2 | AA20: 4.8
A21: The King in Yellow | B21: SSS | C21: TECH | D21: 109 | E21: TECH +15 | F21: CRIT +9% | G21: CRIT DMG +9% | L21: 9 | M21: 9 | R21: 15 | S21: Gold Pack #7 | Y21: 98 | Z21: 1.2 | AA21: 4.9
A22: Goldbach Conjecture | B22: SSS | C22: TECH | D22: 108 | E22: ATK +9% | F22: DMG REDUC +6% | G22: TECH +15 | I22: 9 | O22: 6 | R22: 15 | S22: Traveler's Pack #2 | Y22: 99 | Z22: 1.2 | AA22: 4.9
A23: Superstring Computer | B23: SSS | C23: TECH | D23: 109 | E23: RUSH +9% | F23: DEF +9% | G23: Earth DMG +60 | J23: 9 | K23: 9 | Q23: 60 | S23: Clover Vendor Reward | Y23: 100 | Z23: 1.2 | AA23: 5
A24: TVC Engine | B24: S | C24: TECH | D24: 100 | E24: Earth DMG +60 | Q24: 60 | S24: Lottery Machine No. 3 (1.63%) | Y24: 101 | Z24: 1.2 | AA24: 5
A25: CRISPR | B25: S | C25: TECH | D25: 98 | E25: DEF +9% | K25: 9 | S25: Lottery Machine No. 2 (?%) | Y25: 102 | Z25: 1.2 | AA25: 5.1
Y26: 103 | Z26: 1.2 | AA26: 5.1
Y27: 104 | Z27: 1.3 | AA27: 5.2
Y28: 105 | Z28: 1.3 | AA28: 5.2
Y29: 106 | Z29: 1.3 | AA29: 5.3
Y30: 107 | Z30: 1.3 | AA30: 5.3
C31: Relic | E31: Slot | F31: Stat | G31: =D1 | H31: HP | I31: ATK | J31: RUSH | K31: DEF | L31: CRIT | M31: CRIT DMG | N31: DMG | O31: DMG Reduc | P31: Hero DMG | Q31: ELMT DMG | R31: Alternatives | V31: Boosted | W31: Damage | Y31: 108 | Z31: 1.3 | AA31: 5.4
