Workbook

Sheet Sailing Calculator
A1: Drifter | B1: Current Level | C1: Talent per Lvl | D1: =E22 | E1: =E14 | F1: =E17 | G1: =E13 | H1: Firepower Contributed | I1: Armor Contributed
A2: Peacekeeper | B2: 35 | C2: =VLOOKUP(A2,'Drifter Stats'!$A$4:$Q$24,4,FALSE) | D2: =$I$22*IF(COUNTIF($A$11:$A$14, $F$22)>0, 1, 0) | E2: =$I$14*IF(COUNTIF($A$11:$A$14, $F$14)>0, 1, 0) | G2: =$I$13*IF(COUNTIF($A$11:$A$14, $F$13)>0, 1, 0) | H2: =B2*C2*(1+D2)+E2+F2 | I2: =B2*C2*(1+D2)*10+G2 | S2: Treasure Island | T2: Battle of Sinop | V2: Anecdote | W2: Enemy Seafaring | X2: Enemy Firepower | Y2: Firepower / Seafaring
A3: St. Trinidad | B3: 53 | C3: =VLOOKUP(A3,'Drifter Stats'!$A$4:$Q$24,4,FALSE) | D3: =$I$22*IF(COUNTIF($A$11:$A$14, $F$22)>0, 1, 0) | E3: =$I$14*IF(COUNTIF($A$11:$A$14, $F$14)>0, 1, 0) | G3: =$I$13*IF(COUNTIF($A$11:$A$14, $F$13)>0, 1, 0) | H3: =B3*C3*(1+D3)+E3+F3 | I3: =B3*C3*(1+D3)*10+G3 | S3: 32235 | T3: 34643 | V3: Treasure Island | W3: 58595 | X3: =S46 | Y3: =X3/W3
A4: Soleil Royal | B4: 52 | C4: =VLOOKUP(A4,'Drifter Stats'!$A$4:$Q$24,4,FALSE) | D4: =$I$22*IF(COUNTIF($A$11:$A$14, $F$22)>0, 1, 0) | E4: =$I$14*IF(COUNTIF($A$11:$A$14, $F$14)>0, 1, 0) | F4: =I17*IF(COUNTIF($A$11:$A$14, $F$17)>0, 1, 0)*IF(COUNTIF($A$11:$A$14, $F$14)>0, 1, 0) | G4: =$I$13*IF(COUNTIF($A$11:$A$14, $F$13)>0, 1, 0) | H4: =B4*C4*(1+D4)+E4+F4 | I4: =B4*C4*(1+D4)*10+G4 | S4: 30031 | T4: 35599 | V4: Battle of Sinop | W4: 69249 | X4: =T46 | Y4: =X4/W4
A5: Dragon Horse | B5: 49 | C5: =VLOOKUP(A5,'Drifter Stats'!$A$4:$Q$24,4,FALSE) | D5: =$I$22*IF(COUNTIF($A$11:$A$14, $F$22)>0, 1, 0) | E5: =$I$14*IF(COUNTIF($A$11:$A$14, $F$14)>0, 1, 0) | G5: =$I$13*IF(COUNTIF($A$11:$A$14, $F$13)>0, 1, 0) | H5: =B5*C5*(1+D5)+E5+F5 | I5: =B5*C5*(1+D5)*10+G5 | S5: 30137 | T5: 34103
A6: Tridentman | B6: 42 | C6: =VLOOKUP(A6,'Drifter Stats'!$A$4:$Q$24,4,FALSE) | D6: =$I$22*IF(COUNTIF($A$11:$A$14, $F$22)>0, 1, 0) | E6: =$I$14*IF(COUNTIF($A$11:$A$14, $F$14)>0, 1, 0) | G6: =$I$13*IF(COUNTIF($A$11:$A$14, $F$13)>0, 1, 0) | H6: =B6*C6*(1+D6)+E6+F6 | I6: =B6*C6*(1+D6)*10+G6 | S6: 29961 | T6: 35570
S7: 31164 | T7: 35620
S8: 29630 | T8: 34072
S9: 30670 | T9: 35750
A10: Drifter | B10: Firepower | C10: Armor | E10: Skill Type | F10: Owner | G10: Rating | H10: Level | I10: Effect | J10: % DMG Buff | S10: 29684 | T10: 35299
A11: St. Trinidad | B11: =VLOOKUP(A11,$A$1:$I$6,8,FALSE) | C11: =VLOOKUP(A11,$A$1:$I$6,9,FALSE) | E11: Reduce Damage Taken | F11: Peacekeeper | G11: =IF(H9 >= 10, 'Drifter Priority'!D299, 'Drifter Priority'!C299) | H11: 20 | I11: =0.01*H11 | J11: 0.15233017 | S11: 30022 | T11: 35590
A12: Soleil Royal | B12: =VLOOKUP(A12,$A$1:$I$6,8,FALSE) | C12: =VLOOKUP(A12,$A$1:$I$6,9,FALSE) | E12: Armor Repair/Round | F12: Peacekeeper | G12: =IF(H10 >= 10, 'Drifter Priority'!D298, 'Drifter Priority'!C298) | H12: 20 | I12: =150*H12 | J12: 0.05964886 | S12: 29671 | T12: 35660
A13: Dragon Horse | B13: =VLOOKUP(A13,$A$1:$I$6,8,FALSE) | C13: =VLOOKUP(A13,$A$1:$I$6,9,FALSE) | E13: Ally Armor | F13: Peacekeeper | G13: =IF(H11 >= 10, 'Drifter Priority'!D300, 'Drifter Priority'!C300) | H13: 20 | I13: =1500*H13 | J13: 0.15103911 | S13: 31854 | T13: 35192
A14: Peacekeeper | B14: =VLOOKUP(A14,$A$1:$I$6,8,FALSE) | C14: =VLOOKUP(A14,$A$1:$I$6,9,FALSE) | E14: Ally Firepower | F14: St. Trinidad | G14: =IF(H12 >= 10, 'Drifter Priority'!D314, 'Drifter Priority'!C314) | H14: 20 | I14: =150*H14 | J14: 0.11494276 | S14: 30475 | T14: 36908
E15: Armor Lost Bonus | F15: St. Trinidad | G15: =IF(H13 >= 10, 'Drifter Priority'!D315, 'Drifter Priority'!C315) | H15: 20 | I15: =100*H15 | J15: 0.076172834 | S15: 30284 | T15: 35621
A16: Anecdote | B16: Battle of Midway | E16: Firepower Per Round | F16: St. Trinidad | G16: =IF(H14 >= 10, 'Drifter Priority'!D316, 'Drifter Priority'!C316) | H16: 20 | I16: =70*H16 | J16: 0.070492148 | S16: 31885 | T16: 35873
A17: Stele Choice | B17: DMG REDUC | E17: Firepower Bonus | F17: Soleil Royal | G17: =IF(H15 >= 10, 'Drifter Priority'!D330, 'Drifter Priority'!C330) | H17: 20 | I17: =300*H17 | J17: 0.057471378 | S17: 32203 | T17: 34317
A18: Fleet Firepower | B18: =sum(B11:B14) | E18: CRIT Rate | F18: Soleil Royal | G18: =IF(H16 >= 10, 'Drifter Priority'!D331, 'Drifter Priority'!C331) | H18: 20 | I18: =0.04*H18 | J18: 0.23672238 | S18: 30291 | T18: 34548
A19: Fleet Armor | B19: =sum(C11:C14) | E19: Round 1 DMG | F19: Soleil Royal | G19: =IF(H17 >= 10, 'Drifter Priority'!D332, 'Drifter Priority'!C332) | H19: 20 | I19: =0.25*H19 | J19: 0.10571544 | S19: 30050 | T19: 36612
A20: Enemy Seafaring | B20: =VLOOKUP($B$16,'Rift Anecdotes'!$B$63:$G$85,5,FALSE) | E20: Firepower Reduction | F20: Dragon Horse | G20: =IF(H18 >= 10, 'Drifter Priority'!D188, 'Drifter Priority'!C188) | H20: 20 | I20: =-50*H20 | J20: 0.07700428 | S20: 32274 | T20: 36194
A21: Enemy Firepower | B21: =IF(VLOOKUP($B$16,'Rift Anecdotes'!$B$63:$G$85,6,FALSE) > 0,VLOOKUP($B$16,'Rift Anecdotes'!$B$63:$G$85,6,FALSE), FLOOR(B20*0.52,1)) | E21: CRIT DMG | F21: Dragon Horse | G21: =IF(H19 >= 10, 'Drifter Priority'!D189, 'Drifter Priority'!C189) | H21: 20 | I21: =0.04*H21 | J21: 0.1045 | S21: 31357 | T21: 35521
A22: DMG REDUC | B22: =I11*IF(COUNTIF($A$11:$A$14, $F$11)>0, 1, 0)+IF($B$17=A22, 0.05, 0) | E22: All Drifter Talent | F22: Tridentman | G22: =IF(H20 >= 10, 'Drifter Priority'!D77, 'Drifter Priority'!C77) | H22: 10 | I22: =0.01*H22 | J22: 0.14849765 | S22: 29519 | T22: 34726
A23: Repair/Round | B23: =I12*IF(COUNTIF($A$11:$A$14, $F$11)>0, 1, 0) | E23: Round 1 DMG | F23: Tridentman | G23: =IF(H21 >= 10, 'Drifter Priority'!D76, 'Drifter Priority'!C76) | H23: 10 | I23: =0.25*H23 | J23: 0.12021418 | S23: 30937 | T23: 36540
A24: Firepower/Round | B24: =I16*IF(COUNTIF($A$11:$A$14, $F$16)>0, 1, 0) | J24: Note: Manually Calculated 10->20 | S24: 29904 | T24: 35757
A25: =E18 | B25: =I18*IF(COUNTIF($A$11:$A$14, $F$18)>0, 1, 0)+IF($B$17=A25, 0.05, 0) | S25: 31749 | T25: 36072
A26: CRIT DMG Bonus | B26: =I21*IF(COUNTIF($A$11:$A$14, $F$21)>0, 1, 0) | S26: 30941 | T26: 36243
A27: =E15 | B27: =I15*IF(COUNTIF($A$11:$A$14, $F$15)>0, 1, 0) | S27: 30258 | T27: 36452
A28: =E20 | B28: =I20*IF(COUNTIF($A$11:$A$14, $F$21)>0, 1, 0) | S28: 30974 | T28: 34093
A29: =E21 | B29: =B18*(1.5+B26) | S29: 31870 | T29: 36168
A30: Expected Base Damage | B30: =B18*B25*(1.5+B26)+B18*(1-B25) | S30: 31233 | T30: 34295
A31: First Round DMG | B31: =B18*I19*IF(COUNTIF($A$11:$A$14, $F$19)>0, 1, 0) + B18*I23*IF(COUNTIF($A$11:$A$14, $F$23)>0, 1, 0) | S31: 29242 | T31: 33945
S32: 31764 | T32: 36868
B33: Current | C33: Baseline | S33: 29904 | T33: 35568
A34: Rounds Lasted | B34: {=IFERROR(INDEX(A47:A67, MATCH(0, F47:F67,FALSE)),"All")} | C34: 17 | S34: 30526 | T34: 36672
A35: Damage Dealt | B35: =sum(D47:D67) | C35: 2765816 | S35: 29418 | T35: 33522
S36: 30964 | T36: 35308
A37: Difference | B37: =B35-C35 | S37: 30922 | T37: 36400
A38: Percent | B38: =(B35/C35)-1 | S38: 32043 | T38: 36591
S39: 30196 | T39: 35005
S40: 31515 | T40: 34131
...
